<?xml version="1.0"?>
<robot name="roboduck" xmlns:xacro="http://www.ros.org/wiki/xacro">
    <!-- Propreties -->
    <xacro:arg name="namespace" default="duck"/>
    <xacro:arg name="debug" default="0"/>

    <xacro:arg name="cog" default="0 0 0"/>
    <xacro:arg name="mass" default="0.01"/>
  
    <xacro:arg name="ixx" default="0.0015"/>
    <xacro:arg name="iyy" default="0.0015"/>
    <xacro:arg name="izz" default="0.0015"/>
    <xacro:arg name="ixy" default="0.0"/>
    <xacro:arg name="ixz" default="0.0"/>
    <xacro:arg name="iyz" default="0.0"/>

    <xacro:arg name="mesh_filename" default="$(find biped_descriptions)/meshes/tbi.stl"/>

    <!-- Links -->

    <link name="$(arg namespace)/base_link">
        <inertial>
        <origin xyz="0 0 -0.1" rpy="0 0 0" />
        <mass value="$(arg mass)"/>
        <inertia
            ixx="$(arg ixx)" ixy="$(arg ixy)" ixz="$(arg ixz)"
            iyy="$(arg iyy)" iyz="$(arg iyz)"
            izz="$(arg izz)"/>
        </inertial>
        <visual>
            <origin xyz="0 0 0.0" rpy="0 0 0" />
            <geometry>
                <box size="0.4 0.2 0.2"/>
            </geometry>
        </visual>
        <collision>
            <origin xyz="0 0 0" rpy="0 0 0"/>
            <geometry>
                <box size="0.3 0.2 0.5" />
            </geometry>
        </collision>
    </link>

    <!-- Sphere 1 : 2 rotations -->
    <link name="$(arg namespace)/base_to_hip_left">
        <inertial>
        <origin xyz="$(arg cog)" rpy="0 0 0" />
        <mass value="0.001"/>
        <inertia
            ixx="0.0002" ixy="$(arg ixy)" ixz="$(arg ixz)"
            iyy="0.0002" iyz="$(arg iyz)"
            izz="0.0002"/>
        </inertial>
        <visual>
            <origin xyz="0 0 0.0" rpy="0 0 0" />
            <geometry>
                <sphere radius="0.01"/>
            </geometry>
        </visual>
    </link>

    
    <joint name="$(arg namespace)/hip_joint_left" type="revolute">
        <origin xyz="0.0 0.1 0.0" rpy="0 0 0"/>
        <parent link="$(arg namespace)/base_link"/>
        <child link="$(arg namespace)/base_to_hip_left"/>
        <axis xyz="0 1 1"/>                         
        <limit effort="3.0" velocity="1.0" lower="-1.0" upper="1.0"/>
    </joint>

     <!-- Femur link -->
    <link name="$(arg namespace)/femur_link_left">
        <inertial>
        <origin xyz="$(arg cog)" rpy="0 0 0" />
        <mass value="0.001"/>
        <inertia
            ixx="0.0002" ixy="$(arg ixy)" ixz="$(arg ixz)"
            iyy="0.0002" iyz="$(arg iyz)"
            izz="0.0002"/>
        </inertial>
        <visual>
            <origin xyz="0.0 0.0 0.0" rpy="0 0 0" />
            <geometry>
                <box size="0.01 0.25 0.01"/>
            </geometry>
        </visual>
    </link>

    <joint name="$(arg namespace)/to_hip_joint_left" type="prismatic">
        <origin xyz="0.0 0.13 -0.04" rpy="-0.35 0 0"/>
        <parent link="$(arg namespace)/base_to_hip_left"/>
        <child link="$(arg namespace)/femur_link_left"/>
        <axis xyz="0 0 0"/> 
        <limit effort="0.0" velocity="0.0" lower="0.0" upper="0.0"/> 
    </joint>

    <transmission name="_hip_joint_trans">
        <type>transmission_interface/SimpleTransmission</type>
        <joint name="motor_hip">
            <hardwareInterface>hardware_interface/EffortJointInterface</hardwareInterface>
        </joint>
        <actuator name="_hip_joint_motor">
            <hardwareInterface>hardware_interface/EffortJointInterface</hardwareInterface>
            <mechanicalReduction>1</mechanicalReduction>
        </actuator>
    </transmission>
















































</robot>